Workbook
Name curve_raw_tables: Sheet1!$BY:$BY
Name M_Flow: PumpOG!$CG:$CG
Name M_head: PumpOG!$CE:$CE
Name M_KW: PumpOG!$CF:$CF
Name M_NP: PumpOG!$CI:$CI
Name model_number: Sheet1!$E:$E

Sheet Sheet1
A1: id | B1: organisation_id | C1: name | D1: manufacturer | E1: model_number | F1: size | G1: speed_rpm | H1: impeller_dia_mm | I1: catalogue_report_ids | J1: family_type | K1: impeller_diameters | L1: hq_a0 | M1: hq_a1 | N1: hq_a2 | O1: hq_a3 | P1: hq_a4 | Q1: hq_a5 | R1: eff_b0 | S1: eff_b1 | T1: eff_b2 | U1: eff_b3 | V1: eff_b4 | W1: eff_b5 | X1: npsh_c0 | Y1: npsh_c1 | Z1: npsh_c2 | AA1: npsh_c3 | AB1: npsh_c4 | AC1: npsh_c5 | AD1: pow_p0 | AE1: pow_p1 | AF1: pow_p2 | AG1: pow_p3 | AH1: pow_p4 | AI1: pow_p5 | AJ1: q_min | AK1: q_max | AL1: q_bep | AM1: hr | AN1: qr | AO1: er | AP1: pump_type | AQ1: application | AR1: notes | AS1: extra_curves_json | AT1: graph_show_eff_iso | AU1: graph_eff_levels | AV1: graph_show_power_iso | AW1: graph_power_levels | AX1: graph_show_npsh_iso | AY1: graph_npsh_levels | AZ1: graph_show_npsh_curve | BA1: graph_npsh_yaxis | BB1: graph_show_speed_lines | BC1: graph_speed_line_values | BD1: graph_show_rpm_overlay | BE1: graph_rpm_values | BF1: graph_show_dia_overlay | BG1: graph_dia_overlay_values | BH1: graph_show_hq | BI1: graph_show_other | BJ1: graph_show_eff | BK1: graph_show_power | BL1: graph_show_npsh | BM1: graph_combine_eff_power | BN1: graph_trim_model | BO1: graph_trim_penalty | BP1: selection_allow_fixed_speed | BQ1: selection_allow_vsd | BR1: graph_options_json | BS1: graph_custom_label_pos | BT1: curve_labels | BU1: curve_diameters | BV1: curve_colors | BW1: curve_modes | BX1: curve_units | BY1: curve_raw_tables | BZ1: curve_coeffs | CA1: unit_q | CB1: unit_h | CC1: unit_npsh | CD1: unit_pow | CE1: unit_op_q | CF1: app_modules | CG1: impeller_material | CH1: casing_material | CI1: number_of_vanes | CJ1: suction_size | CK1: discharge_size | CL1: unit_suction | CM1: unit_discharge | CN1: max_solid_size_mm | CO1: unit_solid | CP1: max_pressure_bar | CQ1: unit_pressure | CR1: max_temp_c | CS1: unit_temp | CT1: seal_type | CU1: drive_type | CV1: is_multistage | CW1: num_stages | CX1: is_double_suction | CY1: is_angle_trim | CZ1: is_self_priming | DA1: is_non_clog | DB1: has_inducer | DC1: is_throttling_capable | DD1: min_flow_m3h | DE1: max_orifice_dia_mm | DF1: impeller_eye_area_cm2 | DG1: vfd_min_hz | DH1: vfd_max_hz | DI1: PumpAttribute1 | DJ1: PumpAttribute2 | DK1: PumpAttribute3 | DL1: PumpAttribute4 | DM1: PumpAttribute5 | DN1: PumpAttribute6 | DO1: PumpAttribute7 | DP1: PumpAttribute8 | DQ1: PumpAttribute9 | DR1: PumpAttribute10 | DS1: PumpAttribute11 | DT1: PumpAttribute12 | DU1: PumpAttribute13 | DV1: PumpAttribute14 | DW1: PumpAttribute15 | DX1: PumpAttribute16 | DY1: PumpAttribute17 | DZ1: PumpAttribute18 | EA1: PumpAttribute19 | EB1: PumpAttribute20 | EC1: PumpAttribute21 | ED1: PumpAttribute22 | EE1: PumpAttribute23 | EF1: PumpAttribute24 | EG1: PumpAttribute25 | EH1: PumpAttribute26 | EI1: PumpAttribute27 | EJ1: PumpAttribute28 | EK1: PumpAttribute29 | EL1: PumpAttribute30 | EM1: head_curve_style | EN1: eff_curve_style | EO1: power_curve_style | EP1: npsh_curve_style | EQ1: main_curve_style | ER1: axis_flow_min | ES1: axis_flow_max | ET1: axis_flow_major | EU1: axis_flow_minor | EV1: axis_head_min | EW1: axis_head_max | EX1: axis_head_major | EY1: axis_head_minor | EZ1: axis_eff_min | FA1: axis_eff_max | FB1: axis_eff_major | FC1: axis_eff_minor | FD1: axis_power_min | FE1: axis_power_max | FF1: axis_power_major | FG1: axis_power_minor | FH1: axis_npsh_min | FI1: axis_npsh_max | FJ1: axis_npsh_major | FK1: axis_npsh_minor | FL1: poly_order | FM1: poly_order_hq | FN1: poly_order_eff | FO1: poly_order_npsh | FP1: poly_order_pow | FQ1: created_at | FR1: updated_at
A2: 1 | B2: 1 | C2: Test Pump Filtered | D2: Weir Minerals | E2: 4/3 C-AH | F2: 4/3 C-AH | G2: 1450 | H2: 300 | I2: all | J2: trimmed_impeller | L2: 50 | M2: 0 | N2: -0.0071875 | O2: 0 | P2: 0 | Q2: 0 | R2: -35.555556 | S2: 4.8888889 | T2: -0.055555556 | U2: 0 | V2: 0 | W2: 0 | X2: 1.8 | Y2: 0 | Z2: 0.0012 | AA2: 0 | AB2: 0 | AC2: 0 | AD2: 1.8701 | AE2: 0.11418058 | AF2: -0.0008011192 | AG2: 0 | AH2: 0 | AI2: 0 | AJ2: 0 | AK2: 100 | AL2: 44 | AM2: 0.9 | AN2: 0.92 | AO2: 0.85 | AP2: centrifugal slurry | AQ2: Slurry / mineral processing | AR2: Standard duty slurry pump. Up to 40% w/w abrasive slurry. | AT2: 1 | AU2: 15;30;45 | AV2: 1 | AW2: 5;15;25 | AX2: 1 | AY2: 3;5 | AZ2: 1 | BA2: y2 | BB2: 0 | BD2: 0 | BF2: 1 | BG2: [330;305;280;255;230] | BH2: 1 | BI2: 1 | BJ2: 1 | BK2: 1 | BL2: 1 | BM2: 1 | BN2: both | BO2: NULL | BP2: 1 | BQ2: 1 | BR2: {"show_eff_iso": true, "eff_levels": "15;30;45", "show_power_iso": true, "power_levels": "5;15;25", "show_npsh_iso": true, "npsh_levels": "3;5", "show_npsh_curve": true, "npsh_yaxis": "y2", "show_speed_lines": true, "show_hq": true, "show_other": true, "show_eff": true, "show_power": true, "show_npsh": true, "combine_eff_power": true, "trim_model": "both", "custom_label_pos": {"\u00d8250 mm": {"x": 100, "y": 25}}, "unit_max_imp": "mm", "graph_unit_q": "", "graph_unit_h": "", "graph_unit_npsh": "", "graph_unit_pow": "", "legend_mode": "each"} | BS2: {"\u00d8250 mm": {"x": 100, "y": 25}} | BT2: Curve 1 | BU2: 330.0;mm | BV2: #58a6ff | BW2: fit | BX2: m3h,m,m,kw | BY2: 0.000,46.000,,1.800,1.870;20.000,43.125,40.0,2.280,3.833;30.800,39.182,62.3,2.938,4.627;44.000,32.085,72.0,4.123,5.343;64.000,16.560,49.8,6.715,5.896;80.000,,0.0,9.480,5.877 | BZ2: 46.0,0.0,-0.0071875,0.0,-35.55555555555556,4.888888888888889,-0.05555555555555555,0.0,1.8,0.0,0.0012,1.8701,0.11418058,-0.0008011192,80.00,44.00 | CA2: m3h | CB2: m | CC2: m | CD2: kw | CE2: m3h | CI2: 5 | CL2: mm | CM2: mm | CN2: 0 | CO2: mm | CP2: 0 | CQ2: bar | CR2: 0 | CS2: degC | CV2: 0 | CW2: 1 | CX2: 0 | CY2: 0 | CZ2: 0 | DA2: 0 | DB2: 0 | DC2: 1 | DD2: 0 | DE2: 0 | DF2: 0 | DG2: 30 | DH2: 60 | EM2: #58a6ff;2.0,solid | EN2: #3fb950;1.5,dot | EO2: #f85149;1.5,longdash | EP2: #39d3c0;1.5,dashdot | EQ2: graph | ER2: NULL | ES2: NULL | ET2: NULL | EU2: NULL | EV2: NULL | EW2: NULL | EX2: NULL | EY2: NULL | EZ2: NULL | FA2: NULL | FB2: NULL | FC2: NULL | FD2: NULL | FE2: NULL | FF2: NULL | FG2: NULL | FH2: NULL | FI2: NULL | FJ2: NULL | FK2: NULL | FL2: 4 | FM2: 2 | FN2: 4 | FO2: 3 | FP2: 1 | FQ2: 46196.26 | FR2: 46261.573
A3: 2 | B3: 2 | C3: Warman 6/4 D-AH | D3: Weir Minerals | E3: 6/4 D-AH | F3: 6/4 D-AH | G3: 1000 | H3: 480 | I3: all | J3: trimmed_impeller | L3: 58 | M3: 0 | N3: -0.00047346939 | O3: 0 | P3: 0 | Q3: 0 | R3: -46.618106 | S3: 1.2986472 | T3: -0.0033298647 | U3: 0 | V3: 0 | W3: 0 | X3: 2.2 | Y3: 0 | Z3: 4.5e-05 | AA3: 0 | AB3: 0 | AC3: 0 | AD3: 9.2982 | AE3: 0.12834262 | AF3: -0.0002040423 | AG3: 0 | AH3: 0 | AI3: 0 | AJ3: 0 | AK3: 350 | AL3: 195 | AM3: 0.88 | AN3: 0.9 | AO3: 0.82 | AP3: centrifugal slurry | AQ3: Slurry / tailings | AR3: Heavy duty slurry pump for coarse and abrasive slurries. | AS3: [] | AT3: 1 | AV3: 0 | AX3: 0 | AZ3: 0 | BA3: y2 | BB3: 0 | BD3: 0 | BF3: 1 | BG3: [480;450;420;390;360] | BH3: 1 | BI3: 1 | BJ3: 1 | BK3: 1 | BL3: 1 | BM3: 1 | BN3: fit | BO3: NULL | BP3: 1 | BQ3: 0 | BR3: {"unit_max_imp": "mm", "graph_unit_q": "m3h", "graph_unit_h": "m", "graph_unit_npsh": "m", "graph_unit_pow": "kw", "legend_mode": "each", "label_format": "percent", "custom_label_pos": {}} | BS3: {} | BT3: Curve 1 | BU3: 480.0;mm | BV3: #58a6ff | BW3: fit | BX3: m3h,m,m,kw | BY3: 0.000,58.000,,2.200,9.298;87.500,54.375,41.5,2.545,18.966;136.500,49.178,68.6,3.038,23.015;195.000,39.996,80.0,3.911,26.566;280.000,20.880,55.9,5.728,29.237;350.000,,0.0,7.713,29.223 | BZ3: 58.0,0.0,-0.000473469387755102,0.0,0,0,-46.61810613943808,1.2986472424557753,-0.0033298647242455777,0.0,0,0,2.2,0.0,4.5e-05,0,0,0,9.2982,0.12834262,-0.0002040423,0,0,0,350.00,195.00 | CA3: m3h | CB3: m | CC3: m | CD3: kw | CE3: m3h | CI3: 5 | CL3: mm | CM3: mm | CN3: 0 | CO3: mm | CP3: 0 | CQ3: bar | CR3: 0 | CS3: degC | CV3: 0 | CW3: 1 | CX3: 0 | CY3: 0 | CZ3: 0 | DA3: 0 | DB3: 0 | DC3: 1 | DD3: 0 | DE3: 0 | DF3: 0 | DG3: 30 | DH3: 60 | EM3: #58a6ff;2.0,solid | EN3: #3fb950;1.5,dot | EO3: #f85149;1.5,longdash | EP3: #39d3c0;1.5,dashdot | EQ3: graph | ER3: NULL | ES3: NULL | ET3: NULL | EU3: NULL | EV3: NULL | EW3: NULL | EX3: NULL | EY3: NULL | EZ3: NULL | FA3: NULL | FB3: NULL | FC3: NULL | FD3: NULL | FE3: NULL | FF3: NULL | FG3: NULL | FH3: NULL | FI3: NULL | FJ3: NULL | FK3: NULL | FL3: 3 | FM3: 3 | FN3: 3 | FO3: 2 | FP3: 2 | FQ3: 46196.26 | FR3: 46265.779
A4: 3 | B4: 2 | C4: Warman 8/6 E-AH | D4: Weir Minerals | E4: 8/6 E-AH | F4: 8/6 E-AH | G4: 750 | H4: 610 | I4: all | J4: trimmed_impeller | L4: 72 | M4: 0 | N4: -0.0001125 | O4: 0 | P4: 0 | Q4: 0 | R4: -40.493827 | S4: 0.55679012 | T4: -0.00063271605 | U4: 0 | V4: 0 | W4: 0 | X4: 2.8 | Y4: 0 | Z4: 2.5e-05 | AA4: 0 | AB4: 0 | AC4: 0 | AD4: 25.701 | AE4: 0.15692261 | AF4: -0.0001101008 | AG4: 0 | AH4: 0 | AI4: 0 | AJ4: 0 | AK4: 800 | AL4: 440 | AM4: 0.87 | AN4: 0.9 | AO4: 0.8 | AP4: centrifugal slurry | AQ4: Slurry / coarse solids | AR4: Large slurry pump for high flow, coarse slurry duties. | AT4: 1 | AV4: 0 | AX4: 0 | AZ4: 0 | BA4: y2 | BB4: 0 | BD4: 0 | BF4: 1 | BG4: [610;570;530;490;450] | BH4: 1 | BI4: 1 | BJ4: 1 | BK4: 1 | BL4: 1 | BM4: 1 | BN4: fit | BO4: NULL | BP4: 1 | BQ4: 1 | BS4: {} | CA4: m3h | CB4: m | CC4: m | CD4: kw | CE4: m3h | CI4: 5 | CN4: 0 | CP4: 0 | CR4: 0 | CV4: 0 | CW4: 1 | CX4: 0 | CY4: 0 | CZ4: 0 | DA4: 0 | DB4: 0 | DC4: 1 | DD4: 0 | DE4: 0 | DF4: 0 | DG4: 30 | DH4: 60 | EM4: #58a6ff;2.0,solid | EN4: #3fb950;1.5,dot | EO4: #f85149;1.5,longdash | EP4: #39d3c0;1.5,dashdot | EQ4: graph | ER4: NULL | ES4: NULL | ET4: NULL | EU4: NULL | EV4: NULL | EW4: NULL | EX4: NULL | EY4: NULL | EZ4: NULL | FA4: NULL | FB4: NULL | FC4: NULL | FD4: NULL | FE4: NULL | FF4: NULL | FG4: NULL | FH4: NULL | FI4: NULL | FJ4: NULL | FK4: NULL | FL4: 3 | FM4: 3 | FN4: 3 | FO4: 2 | FP4: 2 | FQ4: 46196.26 | FR4: 46196.26
A5: 4 | B5: 2 | C5: Warman 10/8 F-M | D5: Weir Minerals | E5: 10/8 F-M | F5: 10/8 F-M | G5: 600 | H5: 760 | I5: all | J5: trimmed_impeller | L5: 82 | M5: 0 | N5: -3.203125e-05 | O5: 0 | P5: 0 | Q5: 0 | R5: -39.506173 | S5: 0.27160494 | T5: -0.00015432099 | U5: 0 | V5: 0 | W5: 0 | X5: 3.2 | Y5: 0 | Z5: 1.2e-05 | AA5: 0 | AB5: 0 | AC5: 0 | AD5: 60.0047 | AE5: 0.18318536 | AF5: -6.42637e-05 | AG5: 0 | AH5: 0 | AI5: 0 | AJ5: 0 | AK5: 1600 | AL5: 880 | AM5: 0.86 | AN5: 0.89 | AO5: 0.78 | AP5: centrifugal slurry | AQ5: Mill circuit | AR5: Mill discharge pump for SAG/ball mill circuits. | AT5: 1 | AV5: 0 | AX5: 0 | AZ5: 0 | BA5: y2 | BB5: 0 | BD5: 0 | BF5: 1 | BG5: [760;710;660;610;560] | BH5: 1 | BI5: 1 | BJ5: 1 | BK5: 1 | BL5: 1 | BM5: 1 | BN5: fit | BO5: NULL | BP5: 1 | BQ5: 1 | BS5: {} | CA5: m3h | CB5: m | CC5: m | CD5: kw | CE5: m3h | CI5: 5 | CN5: 0 | CP5: 0 | CR5: 0 | CV5: 0 | CW5: 1 | CX5: 0 | CY5: 0 | CZ5: 0 | DA5: 0 | DB5: 0 | DC5: 1 | DD5: 0 | DE5: 0 | DF5: 0 | DG5: 30 | DH5: 60 | EM5: #58a6ff;2.0,solid | EN5: #3fb950;1.5,dot | EO5: #f85149;1.5,longdash | EP5: #39d3c0;1.5,dashdot | EQ5: graph | ER5: NULL | ES5: NULL | ET5: NULL | EU5: NULL | EV5: NULL | EW5: NULL | EX5: NULL | EY5: NULL | EZ5: NULL | FA5: NULL | FB5: NULL | FC5: NULL | FD5: NULL | FE5: NULL | FF5: NULL | FG5: NULL | FH5: NULL | FI5: NULL | FJ5: NULL | FK5: NULL | FL5: 3 | FM5: 3 | FN5: 3 | FO5: 2 | FP5: 2 | FQ5: 46196.26 | FR5: 46196.26
A6: 5 | B6: 2 | C6: Generic CW 50-200 | D6: Generic | E6: CW50-200 | F6: 50-200 | G6: 2900 | H6: 200 | I6: all | J6: trimmed_impeller | L6: 55 | M6: 0 | N6: -0.11363636 | O6: 0 | P6: 0 | Q6: 0 | R6: -29.92 | S6: 16.32 | T6: -0.68 | U6: 0 | V6: 0 | W6: 0 | X6: 1.2 | Y6: 0 | Z6: 0.04 | AA6: 0 | AB6: 0 | AC6: 0 | AD6: 0.6503 | AE6: 0.14539902 | AF6: -0.0037299845 | AG6: 0 | AH6: 0 | AI6: 0 | AJ6: 0 | AK6: 22 | AL6: 12 | AM6: 1 | AN6: 1 | AO6: 1 | AP6: centrifugal | AQ6: General water service | AR6: Standard end-suction centrifugal pump for water duties. | AS6: [{"label": "Curve 1Manual Trim 1", "color": "#58a6ff", "diameter": 290290, "unit_q": "ls", "unit_h": "m", "unit_npsh": "m", "unit_pow": "kw", "hq_a0": 48, "hq_a1": 0, "hq_a2": -0.0009645062, "hq_a3": 0, "eff_b0": 0, "eff_b1": 1.5625, "eff_b2": -0.0078125, "eff_b3": 0, "npsh_c0": 1, "npsh_c1": 0, "npsh_c2": 0, "pow_p0": 4.6822, "pow_p1": 0.126239, "pow_p2": -0.0003928, "q_max": 144, "q_bep": 99.99}] | AT6: 1 | AV6: 0 | AX6: 0 | AZ6: 0 | BA6: y2 | BB6: 0 | BD6: 0 | BF6: 1 | BG6: [200;185;170;155] | BH6: 1 | BI6: 1 | BJ6: 1 | BK6: 1 | BL6: 1 | BM6: 1 | BN6: fit | BO6: NULL | BP6: 1 | BQ6: 1 | BS6: {} | CA6: m3h | CB6: m | CC6: m | CD6: kw | CE6: m3h | CI6: 5 | CN6: 0 | CP6: 0 | CR6: 0 | CV6: 0 | CW6: 1 | CX6: 0 | CY6: 0 | CZ6: 0 | DA6: 0 | DB6: 0 | DC6: 1 | DD6: 0 | DE6: 0 | DF6: 0 | DG6: 30 | DH6: 60 | EM6: #58a6ff;2.0,solid | EN6: #3fb950;1.5,dot | EO6: #f85149;1.5,longdash | EP6: #39d3c0;1.5,dashdot | EQ6: graph | ER6: NULL | ES6: NULL | ET6: NULL | EU6: NULL | EV6: NULL | EW6: NULL | EX6: NULL | EY6: NULL | EZ6: NULL | FA6: NULL | FB6: NULL | FC6: NULL | FD6: NULL | FE6: NULL | FF6: NULL | FG6: NULL | FH6: NULL | FI6: NULL | FJ6: NULL | FK6: NULL | FL6: 3 | FM6: 3 | FN6: 3 | FO6: 2 | FP6: 2 | FQ6: 46196.26 | FR6: 46258.28
A7: 6 | B7: 2 | C7: Generic CW 100-315 | D7: Generic | E7: CW100-315 | F7: 100-315 | G7: 1450 | H7: 315 | I7: all | J7: variable_speed | L7: 68 | M7: 0 | N7: -0.001088 | O7: 0 | P7: 0 | Q7: 0 | R7: -40.41773 | S7: 1.716199 | T7: -0.0062181122 | U7: 0 | V7: 0 | W7: 0 | X7: 1.8 | Y7: 0 | Z7: 9.5e-05 | AA7: 0 | AB7: 0 | AC7: 0 | AD7: 7.9781 | AE7: 0.15539651 | AF7: -0.0003480523 | AG7: 0 | AH7: 0 | AI7: 0 | AJ7: 0 | AK7: 250 | AL7: 138 | AM7: 1 | AN7: 1 | AO7: 1 | AP7: centrifugal | AQ7: General water / process | AR7: Medium-duty centrifugal pump for water and mild process fluids. | AS7: [{"label": "Curve 1Test Trim", "color": "#58a6ff", "diameter": 280280, "unit_q": "ls", "unit_h": "m", "unit_npsh": "m", "unit_pow": "kw", "hq_a0": 50, "hq_a1": 0, "hq_a2": -0.0009645062, "hq_a3": 0, "eff_b0": 0, "eff_b1": 1.49305556, "eff_b2": -0.0072337963, "eff_b3": 0, "npsh_c0": 1, "npsh_c1": 0, "npsh_c2": 0, "pow_p0": 5.0747, "pow_p1": 0.131362, "pow_p2": -0.00038781, "q_max": 144, "q_bep": 103.17}, {"label": "Curve 2Manual Trim 2", "color": "#3fb950", "diameter": 275, "unit_q": "m3h", "unit_h": "m", "unit_npsh": "m", "unit_pow": "kw", "hq_a0": 46, "hq_a1": 0.025, "hq_a2": -0.01375, "hq_a3": 0, "eff_b0": 0, "eff_b1": 5.5, "eff_b2": -0.1, "eff_b3": 0, "npsh_c0": 1, "npsh_c1": 0, "npsh_c2": 0, "pow_p0": 1.2588, "pow_p1": 0.123613, "pow_p2": -0.00140444, "q_max": 40, "q_bep": 27.51}] | AT7: 1 | AV7: 0 | AX7: 0 | AZ7: 0 | BA7: y2 | BB7: 0 | BD7: 0 | BE7: 1000, 900, 800, 700, 600, 500 | BF7: 1 | BG7: [315;290;265;240] | BH7: 1 | BI7: 1 | BJ7: 1 | BK7: 1 | BL7: 1 | BM7: 1 | BN7: fit | BO7: NULL | BP7: 1 | BQ7: 1 | BR7: {"unit_max_imp": "mm", "graph_unit_q": "m3h", "graph_unit_h": "m", "graph_unit_npsh": "m", "graph_unit_pow": "kw", "legend_mode": "each", "custom_label_pos": {"eta_75": {"x": 133.89, "y": 55.18}, "eta_45": {"x": 226.26, "y": 29.18}, "eta_70": {"x": 187.47, "y": 44.92}}} | BS7: {"eta_75": {"x": 133.89, "y": 55.18}, "eta_45": {"x": 226.26, "y": 29.18}, "eta_70": {"x": 187.47, "y": 44.92}} | BT7: Curve 1;Curve 1Test Trim;Curve 2Manual Trim 2 | BU7: 315.0;mm|280280;mm|275;mm | BV7: #58a6ff;#58a6ff;#3fb950 | BW7: fit;fit;fit | BX7: m3h,m,m,kw|ls,m,m,kw|m3h,m,m,kw | BY7: 0.000,68.000,,1.800,7.978;62.500,63.750,42.6,2.171,16.331;96.600,57.847,67.3,2.686,19.742;138.000,47.280,78.0,3.609,22.795;200.000,24.480,54.1,5.600,25.135;250.000,,,7.737,25.074|| | BZ7: 68.0,0.0,-0.001088,0.0,-40.41772959183673,1.7161989795918366,-0.006218112244897959,0.0,1.8,0.0,9.5e-05,7.9781,0.15539651,-0.0003480523,250.00,138.00|50,0,-0.0009645062,0,0,1.49305556,-0.0072337963,0,1,0,0,5.0747,0.131362,-0.00038781,144,103.17|46,0.025,-0.01375,0,0,5.5,-0.1,0,1,0,0,1.2588,0.123613,-0.00140444,40,27.51 | CA7: m3h | CB7: m | CC7: m | CD7: kw | CE7: m3h | CI7: 5 | CN7: 0 | CP7: 0 | CR7: 0 | CV7: 0 | CW7: 1 | CX7: 0 | CY7: 0 | CZ7: 0 | DA7: 0 | DB7: 0 | DC7: 1 | DD7: 0 | DE7: 0 | DF7: 0 | DG7: 30 | DH7: 60 | EM7: #58a6ff;2.0,solid | EN7: #3fb950;1.5,dot | EO7: #f85149;1.5,longdash | EP7: #39d3c0;1.5,dashdot | EQ7: graph | ER7: NULL | ES7: NULL | ET7: NULL | EU7: NULL | EV7: NULL | EW7: NULL | EX7: NULL | EY7: NULL | EZ7: NULL | FA7: NULL | FB7: NULL | FC7: NULL | FD7: NULL | FE7: NULL | FF7: NULL | FG7: NULL | FH7: NULL | FI7: NULL | FJ7: NULL | FK7: NULL | FL7: 3 | FM7: 3 | FN7: 3 | FO7: 2 | FP7: 2 | FQ7: 46196.26 | FR7: 46263.807
A8: 7 | B8: 2 | C8: KSB Etanorm 32-200 | D8: KSB | E8: Etanorm 32-200 | F8: 32-200 | G8: 2900 | H8: 190 | I8: all | J8: trimmed_impeller | L8: 30 | M8: 0 | N8: -0.1171875 | O8: 0 | P8: 0 | Q8: 0 | R8: -40.489796 | S8: 22.77551 | T8: -1.2653061 | U8: 0 | V8: 0 | W8: 0 | X8: 1 | Y8: 0 | Z8: 0.1 | AA8: 0 | AB8: 0 | AC8: 0 | AD8: 0.2839 | AE8: 0.0850248 | AF8: -0.0029374399 | AG8: 0 | AH8: 0 | AI8: 0 | AJ8: 0 | AK8: 16 | AL8: 9 | AM8: 1 | AN8: 1 | AO8: 1 | AP8: centrifugal | AQ8: Building services / HVAC | AR8: Compact process pump for heating / cooling circuits. | AS8: [] | AT8: 1 | AV8: 0 | AX8: 0 | AZ8: 0 | BA8: y2 | BB8: 0 | BD8: 0 | BF8: 1 | BG8: [190;175;160] | BH8: 1 | BI8: 1 | BJ8: 1 | BK8: 1 | BL8: 1 | BM8: 1 | BN8: fit | BO8: NULL | BP8: 1 | BQ8: 1 | BR8: {"unit_max_imp": "mm", "graph_unit_q": "m3h", "graph_unit_h": "m", "graph_unit_npsh": "m", "graph_unit_pow": "kw", "legend_mode": "each", "custom_label_pos": {"eta_50": {"x": 12.87, "y": 16.24}, "eta_55": {"x": 10.59, "y": 22.92}, "eta_60": {"x": 6.19, "y": 16.61}, "eta_30": {"x": 4.68, "y": 32.76}, "eta_45": {"x": 13.18, "y": 16.44}}, "label_format": "percent"} | BS8: {"eta_50": {"x": 12.87, "y": 16.24}, "eta_55": {"x": 10.59, "y": 22.92}, "eta_60": {"x": 6.19, "y": 16.61}, "eta_30": {"x": 4.68, "y": 32.76}, "eta_45": {"x": 13.18, "y": 16.44}} | BT8: Curve 1 | BU8: 190.0;mm | BV8: #58a6ff | BW8: fit | BX8: m3h,m,m,kw | BY8: 0.000,30.000,,1.000,0.284;4.000,28.125,30.4,2.600,0.577;6.300,25.349,52.8,4.969,0.703;9.000,20.508,62.0,9.100,0.811;12.800,10.800,43.7,17.384,0.891;16.000,,,26.600,0.892 | BZ8: 30.0,0.0,-0.1171875,0.0,0,0,-40.48979591836735,22.775510204081634,-1.2653061224489797,0.0,0,0,1.0,0.0,0.1,0,0,0,0.2839,0.0850248,-0.0029374399,0,0,0,16.00,9.00 | CA8: m3h | CB8: m | CC8: m | CD8: kw | CE8: m3h | CI8: 5 | CL8: mm | CM8: mm | CN8: 0 | CO8: mm | CP8: 0 | CQ8: bar | CR8: 0 | CS8: degC | CV8: 0 | CW8: 1 | CX8: 0 | CY8: 0 | CZ8: 0 | DA8: 0 | DB8: 0 | DC8: 1 | DD8: 0 | DE8: 0 | DF8: 0 | DG8: 30 | DH8: 60 | DI8: open | DJ8: ANSI | DK8: 6 | DM8: Rubber | EM8: #58a6ff;2.0,solid | EN8: #3fb950;1.5,dot | EO8: #f85149;1.5,longdash | EP8: #39d3c0;1.5,dashdot | EQ8: graph | ER8: NULL | ES8: NULL | ET8: NULL | EU8: NULL | EV8: NULL | EW8: NULL | EX8: NULL | EY8: NULL | EZ8: NULL | FA8: NULL | FB8: NULL | FC8: NULL | FD8: NULL | FE8: NULL | FF8: NULL | FG8: NULL | FH8: NULL | FI8: NULL | FJ8: NULL | FK8: NULL | FL8: 3 | FM8: 3 | FN8: 3 | FO8: 2 | FP8: 2 | FQ8: 46196.26 | FR8: 46268.563
A9: 9 | B9: 2 | C9: ISF100x65-200 2P | D9: APEX PUMPS | E9: ISF100x65-200 | G9: 2900 | H9: 282 | I9: all | J9: trimmed_impeller | L9: 69.996949 | M9: 0.00501678 | N9: 0.0005897238 | O9: -7.466356e-06 | P9: 9.4089e-09 | Q9: 0 | R9: 0.368878 | S9: 1.2613619 | T9: -0.0062642612 | U9: 9.167406e-06 | V9: 0 | W9: 0 | X9: 2.614652 | Y9: -0.01680064 | Z9: 0.0001301316 | AA9: 0 | AB9: 0 | AC9: 0 | AD9: 11.9889 | AE9: 0.143352 | AF9: 0.00014407 | AG9: -1.2772e-06 | AH9: 0 | AI9: 0 | AJ9: 0 | AK9: 203.58 | AL9: 150.34 | AM9: 1 | AN9: 1 | AO9: 1 | AP9: centrifugal | AQ9: Process | AR9: Test notes | AS9: [{"label":"Curve 2","color":"#127ef3","diameter":"182","unit_dia":"mm","curve_mode":"affinity","unit_q":"ls","unit_h":"m","unit_npsh":"m","unit_pow":"kw","style_mode":"custom","use_custom_style":true,"weight":3,"style":"dot","raw_table":[["0","41.27","0","2.41","6.5"],["10.2","41.74","44.82","2.41","9.32"],["20.04","41.42","65.45","2.41","12.44"],["26.72","39.8","72.27","2.45","14.44"],["33.4","36.67","74.98","2.8","16.02"],["40.08","31.84","72.83","3.8","17.19"],["43.42","28.66","69.09","5","17.67"]]}] | AT9: 1 | AU9: 30;40;50;60;75;78 | AV9: 1 | AW9: 10;15;20;35;30;40 | AX9: 1 | AY9: 1.5;2.5;3.5;4.5 | AZ9: 0 | BA9: y1 | BB9: 0 | BC9: 2900;2100;1450;750 | BD9: 0 | BE9: 2900, 2000, 1000 | BF9: 1 | BG9: 228;213;197;182 | BH9: 1 | BI9: 1 | BJ9: 1 | BK9: 1 | BL9: 1 | BM9: 0 | BN9: fit | BO9: NULL | BP9: 1 | BQ9: 0 | BR9: {"unit_max_imp": "mm", "graph_unit_q": "ls", "graph_unit_h": "m", "graph_unit_npsh": "m", "graph_unit_pow": "kw", "legend_mode": "curve_labels", "curve_label_flow_pct": 100, "curve_label_vpos": "top", "curve_label_pos": "middle-top", "custom_label_pos": {"\u00d8182 mm (Affinity)": {"x": 179.04, "y": 28.92}, "\u00d8182 mm (Fitted)": {"x": 271.66, "y": 39.7}, "\u00d8228 mm": {"x": 216.07, "y": 47.33}, "eta_30": {"x": 97.42, "y": 74.34}, "eta_40": {"x": 142.16, "y": 74.47}, "\u00d8228.0 mm": {"x": 125, "y": 48}, "\u00d8197 mm": {"x": 183.85, "y": 34.45}, "eta_75": {"x": 108.99, "y": 72.32}, "npsh_4.5": {"x": 169.99, "y": 61.93}, "\u00d8213 mm": {"x": 197.75, "y": 40.59}, "eta_78": {"x": 185, "y": 59.7}, "eta_50": {"x": 185.54, "y": 75.37}, "npsh_2": {"x": 105.01, "y": 56.97}, "eta_60": {"x": 244.4, "y": 74.82}, "npsh_2.5": {"x": 123.52, "y": 52.88}, "npsh_3": {"x": 150.55, "y": 48.48}, "npsh_1.5": {"x": 275.4, "y": 47.89}, "eta_75_4": {"x": 107.66, "y": 71.86}, "npsh_4.5_5": {"x": 189.08, "y": 48.46}, "eta_75_5": {"x": 208.4, "y": 51.11}, "eta_78_7": {"x": 183.66, "y": 58.23}, "eta_30_0": {"x": 97.42, "y": 73.57}, "eta_78_6": {"x": 125.86, "y": 71.79}, "eff_\u00d8197 mm": {"x": 182.74, "y": 68.81}, "eff_\u00d8228 mm": {"x": 208.15, "y": 73.42}, "pow_\u00d8182 mm": {"x": 180.79, "y": 18.64}, "npsh_\u00d8182 mm": {"x": 171.29, "y": 2.81}, "eff_\u00d8213 mm": {"x": 197.03, "y": 71.03}, "eff_spd_3": {"x": 13.46, "y": 63.67}, "\u00d8182 mm": {"x": 173.59, "y": 29.12}, "eff_\u00d8182 mm": {"x": 166, "y": 69.32}, "eff_spd_0": {"x": 214.85, "y": 67.56}, "eff_spd_2": {"x": 113.72, "y": 66.44}, "eff_spd_1": {"x": 156.74, "y": 69.22}, "\u00d8213 mm (93%)": {"x": 209.41, "y": 40.29}, "\u00d8182 mm (80%)": {"x": 178.49, "y": 28.29}, "\u00d8197 mm (86%)": {"x": 194.83, "y": 34.03}, "pow_\u00d8182 mm (80%)": {"x": 176.36, "y": 18.67}, "pow_\u00d8197 mm (86%)": {"x": 207.68, "y": 22.82}, "pow_\u00d8228 mm (100%)": {"x": 229.75, "y": 38.36}, "eff_\u00d8228 mm (100%)": {"x": 210.92, "y": 73.82}, "eff_\u00d8213 mm (93%)": {"x": 197.14, "y": 70.45}, "eff_\u00d8197 mm (86%)": {"x": 180.04, "y": 68.97}, "eff_\u00d8182 mm (80%)": {"x": 171.32, "y": 67.69}, "spd_lbl_1": {"x": 164.27, "y": 22.72}, "spd_lbl_0": {"x": 213.59, "y": 45.65}, "npsh_4.5_3": {"x": 196.45, "y": 46.45}, "pow_spd_1": {"x": 168.05, "y": 16}, "pow_spd_2": {"x": 114.16, "y": 6}, "pow_spd_3": {"x": 66.53, "y": 0.67}, "npsh_spd_3": {"x": 62.35, "y": 0.21}, "npsh_spd_2": {"x": 115.81, "y": 1.12}, "npsh_\u00d8228 mm (100%)": {"x": 216.32, "y": 4.25}, "pow_spd_0": {"x": 162.61, "y": 34.67}, "pow_dia_0": {"x": 217.33, "y": 37.56}, "eff_dia_3": {"x": 167.83, "y": 66.83}, "pow_dia_3": {"x": 178.88, "y": 18}, "pow_dia_2": {"x": 193.93, "y": 24.44}, "spd_lbl_2": {"x": 111.64, "y": 6.96}, "dia_lbl_3": {"x": 132.67, "y": 30.43}, "dia_lbl_2": {"x": 187.67, "y": 35.79}, "dia_lbl_1": {"x": 199.37, "y": 40.32}, "eff_dia_2": {"x": 181.94, "y": 69.06}, "eff_dia_1": {"x": 197.35, "y": 72.11}, "eff_dia_0": {"x": 210.28, "y": 73.78}, "eta_40_left": {"x": 38.09, "y": 74.45}, "eta_30_left": {"x": 25.56, "y": 73.92}, "eta_50_left": {"x": 53.57, "y": 75.52}, "eta_60_left": {"x": 73.62, "y": 74.99}, "eta_75_left": {"x": 107.03, "y": 73.92}, "dia_lbl_0": {"x": 214.42, "y": 47.52}, "eta_75_right": {"x": 208.91, "y": 52.59}, "spd_lbl_3": {"x": 64.84, "y": 1.92}, "pow_30_4": {"x": 150.08, "y": 59.23}, "pow_20_2": {"x": 85.32, "y": 61.63}, "npsh_2.5_1": {"x": 140.04, "y": 52.03}, "npsh_3.5_2": {"x": 175.57, "y": 43.49}, "npsh_spd_1": {"x": 160.92, "y": 2.34}, "npsh_spd_0": {"x": 157.18, "y": 3.26}, "npsh_dia_0": {"x": 209.45, "y": 4.56}, "npsh_dia_1": {"x": 196.92, "y": 3.97}, "npsh_dia_2": {"x": 181.87, "y": 3.41}, "npsh_dia_3": {"x": 167.47, "y": 2.91}, "pow_dia_1": {"x": 206.46, "y": 29.33}, "pow_15_1": {"x": 56.48, "y": 56.29}, "pow_35_3": {"x": 185.18, "y": 50.72}, "eta_78_right": {"x": 183.49, "y": 60.59}, "eta_78_left": {"x": 127.08, "y": 72.32}, "pow_10_0": {"x": 31.43, "y": 48.83}, "npsh_1.5_0": {"x": 80.32, "y": 47.36}, "\u00d8228 mm (100%)": {"x": 226.4, "y": 45.63}, "pow_\u00d8197 mm": {"x": 195.19, "y": 24.64}, "pow_\u00d8213 mm": {"x": 205.63, "y": 30.42}, "pow_\u00d8228 mm": {"x": 213.59, "y": 36.64}, "npsh_\u00d8197 mm": {"x": 184.43, "y": 3.46}, "npsh_\u00d8213 mm": {"x": 198.18, "y": 3.98}, "npsh_\u00d8228 mm": {"x": 211.68, "y": 4.54}, "eff_750 RPM (26%)": {"x": 22.21, "y": 65.33}, "eff_1450 RPM (50%)": {"x": 109.12, "y": 68.11}, "eff_2100 RPM (72%)": {"x": 165.24, "y": 72.39}, "eff_2900 RPM (100%)": {"x": 208.87, "y": 66.56}, "750 RPM (26%)": {"x": 74.27, "y": 2.85}, "1450 RPM (50%)": {"x": 121.25, "y": 10.56}, "2100 RPM (72%)": {"x": 165.28, "y": 34.35}, "2900 RPM (100%)": {"x": 223.02, "y": 45.03}, "pow_1450 RPM (50%)": {"x": 125.03, "y": 4.04}, "pow_2100 RPM (72%)": {"x": 152.28, "y": 13.46}, "pow_2900 RPM (100%)": {"x": 225.61, "y": 35.97}, "pow_\u00d8213 mm (93%)": {"x": 217.76, "y": 29.4}, "npsh_\u00d8182 mm (80%)": {"x": 158.8, "y": 2.11}, "npsh_\u00d8197 mm (86%)": {"x": 186.59, "y": 3}, "npsh_\u00d8213 mm (93%)": {"x": 192.35, "y": 3.69}, "1000 RPM (34%)": {"x": 94.93, "y": 3.76}, "eff_1000 RPM (34%)": {"x": 27.25, "y": 65.28}, "eff_2000 RPM (69%)": {"x": 140.87, "y": 67.5}, "pow_1000 RPM (34%)": {"x": 97.02, "y": 2.64}, "pow_2000 RPM (69%)": {"x": 159.26, "y": 11.76}, "npsh_1000 RPM (34%)": {"x": 91.22, "y": 0.56}, "npsh_2900 RPM (100%)": {"x": 243.43, "y": 4.54}, "npsh_2000 RPM (69%)": {"x": 179.57, "y": 2.2}}, "label_format": "simple"} | BS9: {"\u00d8182 mm (Affinity)": {"x": 179.04, "y": 28.92}, "\u00d8182 mm (Fitted)": {"x": 271.66, "y": 39.7}, "\u00d8228 mm": {"x": 216.07, "y": 47.33}, "eta_30": {"x": 97.42, "y": 74.34}, "eta_40": {"x": 142.16, "y": 74.47}, "\u00d8228.0 mm": {"x": 125, "y": 48}, "\u00d8197 mm": {"x": 183.85, "y": 34.45}, "eta_75": {"x": 108.99, "y": 72.32}, "npsh_4.5": {"x": 169.99, "y": 61.93}, "\u00d8213 mm": {"x": 197.75, "y": 40.59}, "eta_78": {"x": 185, "y": 59.7}, "eta_50": {"x": 185.54, "y": 75.37}, "npsh_2": {"x": 105.01, "y": 56.97}, "eta_60": {"x": 244.4, "y": 74.82}, "npsh_2.5": {"x": 123.52, "y": 52.88}, "npsh_3": {"x": 150.55, "y": 48.48}, "npsh_1.5": {"x": 275.4, "y": 47.89}, "eta_75_4": {"x": 107.66, "y": 71.86}, "npsh_4.5_5": {"x": 189.08, "y": 48.46}, "eta_75_5": {"x": 208.4, "y": 51.11}, "eta_78_7": {"x": 183.66, "y": 58.23}, "eta_30_0": {"x": 97.42, "y": 73.57}, "eta_78_6": {"x": 125.86, "y": 71.79}, "eff_\u00d8197 mm": {"x": 182.74, "y": 68.81}, "eff_\u00d8228 mm": {"x": 208.15, "y": 73.42}, "pow_\u00d8182 mm": {"x": 180.79, "y": 18.64}, "npsh_\u00d8182 mm": {"x": 171.29, "y": 2.81}, "eff_\u00d8213 mm": {"x": 197.03, "y": 71.03}, "eff_spd_3": {"x": 13.46, "y": 63.67}, "\u00d8182 mm": {"x": 173.59, "y": 29.12}, "eff_\u00d8182 mm": {"x": 166, "y": 69.32}, "eff_spd_0": {"x": 214.85, "y": 67.56}, "eff_spd_2": {"x": 113.72, "y": 66.44}, "eff_spd_1": {"x": 156.74, "y": 69.22}, "\u00d8213 mm (93%)": {"x": 209.41, "y": 40.29}, "\u00d8182 mm (80%)": {"x": 178.49, "y": 28.29}, "\u00d8197 mm (86%)": {"x": 194.83, "y": 34.03}, "pow_\u00d8182 mm (80%)": {"x": 176.36, "y": 18.67}, "pow_\u00d8197 mm (86%)": {"x": 207.68, "y": 22.82}, "pow_\u00d8228 mm (100%)": {"x": 229.75, "y": 38.36}, "eff_\u00d8228 mm (100%)": {"x": 210.92, "y": 73.82}, "eff_\u00d8213 mm (93%)": {"x": 197.14, "y": 70.45}, "eff_\u00d8197 mm (86%)": {"x": 180.04, "y": 68.97}, "eff_\u00d8182 mm (80%)": {"x": 171.32, "y": 67.69}, "spd_lbl_1": {"x": 164.27, "y": 22.72}, "spd_lbl_0": {"x": 213.59, "y": 45.65}, "npsh_4.5_3": {"x": 196.45, "y": 46.45}, "pow_spd_1": {"x": 168.05, "y": 16}, "pow_spd_2": {"x": 114.16, "y": 6}, "pow_spd_3": {"x": 66.53, "y": 0.67}, "npsh_spd_3": {"x": 62.35, "y": 0.21}, "npsh_spd_2": {"x": 115.81, "y": 1.12}, "npsh_\u00d8228 mm (100%)": {"x": 216.32, "y": 4.25}, "pow_spd_0": {"x": 162.61, "y": 34.67}, "pow_dia_0": {"x": 217.33, "y": 37.56}, "eff_dia_3": {"x": 167.83, "y": 66.83}, "pow_dia_3": {"x": 178.88, "y": 18}, "pow_dia_2": {"x": 193.93, "y": 24.44}, "spd_lbl_2": {"x": 111.64, "y": 6.96}, "dia_lbl_3": {"x": 132.67, "y": 30.43}, "dia_lbl_2": {"x": 187.67, "y": 35.79}, "dia_lbl_1": {"x": 199.37, "y": 40.32}, "eff_dia_2": {"x": 181.94, "y": 69.06}, "eff_dia_1": {"x": 197.35, "y": 72.11}, "eff_dia_0": {"x": 210.28, "y": 73.78}, "eta_40_left": {"x": 38.09, "y": 74.45}, "eta_30_left": {"x": 25.56, "y": 73.92}, "eta_50_left": {"x": 53.57, "y": 75.52}, "eta_60_left": {"x": 73.62, "y": 74.99}, "eta_75_left": {"x": 107.03, "y": 73.92}, "dia_lbl_0": {"x": 214.42, "y": 47.52}, "eta_75_right": {"x": 208.91, "y": 52.59}, "spd_lbl_3": {"x": 64.84, "y": 1.92}, "pow_30_4": {"x": 150.08, "y": 59.23}, "pow_20_2": {"x": 85.32, "y": 61.63}, "npsh_2.5_1": {"x": 140.04, "y": 52.03}, "npsh_3.5_2": {"x": 175.57, "y": 43.49}, "npsh_spd_1": {"x": 160.92, "y": 2.34}, "npsh_spd_0": {"x": 157.18, "y": 3.26}, "npsh_dia_0": {"x": 209.45, "y": 4.56}, "npsh_dia_1": {"x": 196.92, "y": 3.97}, "npsh_dia_2": {"x": 181.87, "y": 3.41}, "npsh_dia_3": {"x": 167.47, "y": 2.91}, "pow_dia_1": {"x": 206.46, "y": 29.33}, "pow_15_1": {"x": 56.48, "y": 56.29}, "pow_35_3": {"x": 185.18, "y": 50.72}, "eta_78_right": {"x": 183.49, "y": 60.59}, "eta_78_left": {"x": 127.08, "y": 72.32}, "pow_10_0": {"x": 31.43, "y": 48.83}, "npsh_1.5_0": {"x": 80.32, "y": 47.36}, "\u00d8228 mm (100%)": {"x": 226.4, "y": 45.63}, "pow_\u00d8197 mm": {"x": 195.19, "y": 24.64}, "pow_\u00d8213 mm": {"x": 205.63, "y": 30.42}, "pow_\u00d8228 mm": {"x": 213.59, "y": 36.64}, "npsh_\u00d8197 mm": {"x": 184.43, "y": 3.46}, "npsh_\u00d8213 mm": {"x": 198.18, "y": 3.98}, "npsh_\u00d8228 mm": {"x": 211.68, "y": 4.54}, "eff_750 RPM (26%)": {"x": 22.21, "y": 65.33}, "eff_1450 RPM (50%)": {"x": 109.12, "y": 68.11}, "eff_2100 RPM (72%)": {"x": 165.24, "y": 72.39}, "eff_2900 RPM (100%)": {"x": 208.87, "y": 66.56}, "750 RPM (26%)": {"x": 74.27, "y": 2.85}, "1450 RPM (50%)": {"x": 121.25, "y": 10.56}, "2100 RPM (72%)": {"x": 165.28, "y": 34.35}, "2900 RPM (100%)": {"x": 223.02, "y": 45.03}, "pow_1450 RPM (50%)": {"x": 125.03, "y": 4.04}, "pow_2100 RPM (72%)": {"x": 152.28, "y": 13.46}, "pow_2900 RPM (100%)": {"x": 225.61, "y": 35.97}, "pow_\u00d8213 mm (93%)": {"x": 217.76, "y": 29.4}, "npsh_\u00d8182 mm (80%)": {"x": 158.8, "y": 2.11}, "npsh_\u00d8197 mm (86%)": {"x": 186.59, "y": 3}, "npsh_\u00d8213 mm (93%)": {"x": 192.35, "y": 3.69}, "1000 RPM (34%)": {"x": 94.93, "y": 3.76}, "eff_1000 RPM (34%)": {"x": 27.25, "y": 65.28}, "eff_2000 RPM (69%)": {"x": 140.87, "y": 67.5}, "pow_1000 RPM (34%)": {"x": 97.02, "y": 2.64}, "pow_2000 RPM (69%)": {"x": 159.26, "y": 11.76}, "npsh_1000 RPM (34%)": {"x": 91.22, "y": 0.56}, "npsh_2900 RPM (100%)": {"x": 243.43, "y": 4.54}, "npsh_2000 RPM (69%)": {"x": 179.57, "y": 2.2}} | BT9: MainCurve;Curve 2 | BU9: 228.0;mm|182;mm | BV9: #58a6ff;#127ef3 | BW9: fit;affinity | BX9: ls,m,m,kw|ls,m,m,kw | BY9: 0,70,0,2.41,12.0;13.05,70.79,48,2.41,18.88;26.1,70.25,70.1,2.41,25.66;34.8,67.5,77.4,2.45,29.77;43.5,62.2,80.3,2.8,33.05;52.2,54,78,3.8,35.45;56.55,48.6,74,5,36.43|0,41.27,0,2.41,6.5;10.2,41.74,44.82,2.41,9.32;20.04,41.42,65.45,2.41,12.44;26.72,39.8,72.27,2.45,14.44;33.4,36.67,74.98,2.8,16.02;40.08,31.84,72.83,3.8,17.19;43.42,28.66,69.09,5,17.67 | BZ9: 69.996949,0.00501678,0.0005897238,-7.466356e-06,9.4089e-09,0,0.368878,1.26136189,-0.0062642612,9.167406e-06,0,0,2.614652,-0.01680064,0.0001301316,0,0,0,11.9889,0.143352,0.00014407,-1.2772e-06,0,0,203.58,150.34|41.268237,0.00332502,0.0006080229,-0.000009913106,0,0,0,0,0,0,0,0,0,0,0,0,0,0,0,0,0,0,0,0,0,0 | CA9: ls | CB9: m | CC9: m | CD9: kw | CE9: m3h | CI9: 5 | CL9: mm | CM9: mm | CN9: 0 | CO9: mm | CP9: 0 | CQ9: bar | CR9: 0 | CS9: degC | CV9: 0 | CW9: 1 | CX9: 0 | CY9: 0 | CZ9: 0 | DA9: 0 | DB9: 0 | DC9: 1 | DD9: 0 | DE9: 0 | DF9: 0 | DG9: 30 | DH9: 60 | DI9: Closed | DJ9: ISO | DK9: 5 | DM9: Metal | EM9: #b0788e;1.5,solid | EN9: #b2ba40;1.5,dot | EO9: #f85149;1.5,longdash | EP9: #55918c;1.5,dashdot | EQ9: graph | ER9: 0 | ES9: 60 | ET9: 6 | EU9: 5 | EV9: 0 | EW9: 80 | EX9: 4 | EY9: 6 | EZ9: 0 | FA9: 80 | FB9: 4 | FC9: 2 | FD9: 0 | FE9: 40 | FF9: 4 | FG9: 2 | FH9: 0 | FI9: 5 | FJ9: 5 | FK9: 2 | FL9: 2 | FM9: 4 | FN9: 3 | FO9: 2 | FP9: 3 | FQ9: 46221.44 | FR9: 46267.826
A10: 23 | B10: 2 | C10: VS150S-METAL | D10: SPSA | E10: VS150 | G10: 1000 | H10: 480 | I10: all | J10: variable_speed | L10: 37.302156 | M10: 0.00294195 | N10: -5.55862e-05 | O10: 3.1747e-08 | P10: 0 | Q10: 0 | R10: 2.213968 | S10: 0.23673272 | T10: -0.0002502779 | U10: 0 | V10: 0 | W10: 0 | X10: 0 | Y10: 0 | Z10: 0 | AA10: 0 | AB10: 0 | AC10: 0 | AD10: 36.0275 | AE10: 0.043395 | AF10: 8.859e-05 | AG10: -6.66e-08 | AH10: 0 | AI10: 0 | AJ10: 0 | AK10: 651.6 | AL10: 472.57 | AM10: 1 | AN10: 1 | AO10: 1 | AP10: centrifugal | AS10: [] | AT10: 1 | AU10: 20;30;40;45;50;52 | AV10: 1 | AW10: 10;20;30;40;50;60;70;80 | AX10: 0 | AZ10: 0 | BA10: y2 | BB10: 0 | BD10: 1 | BE10: 1000;900;800;700;600;500 | BF10: 0 | BG10: 480;320;240;180 | BH10: 1 | BI10: 1 | BJ10: 1 | BK10: 1 | BL10: 0 | BM10: 0 | BN10: fit | BO10: NULL | BP10: 1 | BQ10: 1 | BR10: {"unit_max_imp": "mm", "graph_unit_q": "ls", "graph_unit_h": "m", "graph_unit_npsh": "m", "graph_unit_pow": "kw", "legend_mode": "curve_labels", "custom_label_pos": {"spd_lbl_3": {"x": 140.85555555555555, "y": 11.76}, "eff_\u00d8900 mm": {"x": 586.44, "y": 48.71}, "pow_500 RPM": {"x": 367.02, "y": 9.72}, "eff_\u00d8500 mm": {"x": 325.8, "y": 46.21}, "eff_\u00d8600 mm": {"x": 409.76, "y": 60.71}, "spd_lbl_2": {"x": 160.62, "y": 14.87}, "500 RPM": {"x": 374.08, "y": 4.8}, "eff_spd_2": {"x": 150.85, "y": 47.85}, "eff_600 RPM": {"x": 389.3, "y": 47.06}, "eff_spd_3": {"x": 132.33, "y": 48.68}, "eff_500 RPM": {"x": 328.14, "y": 44.11}, "pow_700 RPM": {"x": 514.08, "y": 25.29}, "spd_lbl_0": {"x": 206.54, "y": 23.87}, "pow_800 RPM": {"x": 581.36, "y": 39.46}, "spd_lbl_1": {"x": 170.17, "y": 19.87}, "eff_spd_8": {"x": 436.58, "y": 54.62}, "spd_lbl_8": {"x": 345.08, "y": 6.54}, "eff_spd_6": {"x": 509.99, "y": 48.32}, "eff_spd_1": {"x": 167.62, "y": 48.4}, "spd_lbl_5": {"x": 105.23888888888891, "y": 4.6}, "spd_lbl_4": {"x": 124.4, "y": 7.84}, "pow_70_6": {"x": 545.36, "y": 25.1}, "eff_spd_0": {"x": 188.23, "y": 48.26}, "eff_spd_4": {"x": 111.36, "y": 48.82}, "pow_spd_1": {"x": 166.86, "y": 60.1}, "pow_spd_2": {"x": 156.24, "y": 43.02}, "pow_spd_3": {"x": 140.31, "y": 31.3}, "pow_spd_0": {"x": 195.68, "y": 81.25}, "pow_spd_4": {"x": 122.62, "y": 19.58}, "pow_spd_5": {"x": 99.62, "y": 7.37}, "eta_50_left": {"x": 296.95, "y": 35.53}, "eta_40_left": {"x": 210.44, "y": 37.95}, "eff_spd_5": {"x": 314.1, "y": 48.82}, "dia_lbl_1": {"x": 164.82222222222225, "y": 16.54}, "dia_lbl_2": {"x": 109.06666666666668, "y": 5.49}, "eta_45_left": {"x": 257.4, "y": 37.28}, "eta_50_6": {"x": 298.8, "y": 36.31}, "eta_52_7": {"x": 194.52222222222224, "y": 26.78}, "eta_30_left": {"x": 146.28, "y": 38.36}, "dia_lbl_3": {"x": 446.87, "y": 2.58}, "eta_20_left": {"x": 94.96, "y": 38.49}, "dia_lbl_0": {"x": 197.66666666666669, "y": 22.7}, "eff_dia_3": {"x": 102.34, "y": 52.17}, "eff_dia_2": {"x": 94.24722222222223, "y": 47.17}, "eff_dia_1": {"x": 125.40555555555557, "y": 43.83}, "eff_dia_0": {"x": 188.07222222222222, "y": 43.28}, "pow_dia_1": {"x": 133.45555555555558, "y": 23.58}, "pow_dia_0": {"x": 148.86111111111111, "y": 76.31}, "pow_dia_2": {"x": 105.10000000000001, "y": 11.38}, "pow_50_4": {"x": 413.93, "y": 25.2}, "pow_80_7": {"x": 638.03, "y": 22.85}, "pow_dia_3": {"x": 282.65, "y": 5.52}, "eta_40_right": {"x": 312.9, "y": 5.22}, "eta_52_left": {"x": 329.47, "y": 35.1}, "eta_52_right": {"x": 649.58, "y": 26.87}, "pow_20_1": {"x": 297.72, "y": 13.79}, "pow_40_3": {"x": 365.54, "y": 22.27}, "eta_45_right": {"x": 502.49, "y": 14.03}, "pow_30_2": {"x": 332.64, "y": 17.52}, "eta_50_right": {"x": 625.39, "y": 27.7}, "pow_10_0": {"x": 227.56, "y": 9.69}, "pow_600 RPM": {"x": 436.32, "y": 18.02}, "pow_900 RPM": {"x": 646.27, "y": 60.35}, "pow_1000 RPM": {"x": 711.79, "y": 89.74}, "undefined RPM": {"x": 174.89, "y": 20.17}, "1000 RPM": {"x": 710.24, "y": 23.52}, "600 RPM": {"x": 433.01, "y": 7.75}, "700 RPM": {"x": 490.54, "y": 10.85}, "800 RPM": {"x": 557.32, "y": 14.93}, "900 RPM": {"x": 625.39, "y": 19.18}, "eff_900 RPM": {"x": 588.71, "y": 44}, "eff_1000 RPM": {"x": 668.52, "y": 47}, "eff_700 RPM": {"x": 456.95, "y": 45.94}, "eff_800 RPM": {"x": 514.04, "y": 43.5}, "eff_500 RPM (50%)": {"x": 93.63, "y": 48.61}, "eff_600 RPM (60%)": {"x": 110.82, "y": 48.89}, "eff_700 RPM (70%)": {"x": 127.85, "y": 48.47}, "eff_800 RPM (80%)": {"x": 147.08, "y": 47.78}, "eff_900 RPM (90%)": {"x": 165.85, "y": 48.33}, "eff_1000 RPM (100%)": {"x": 182.36, "y": 48.75}, "pow_500 RPM (50%)": {"x": 100.59, "y": 14.11}, "pow_60_5": {"x": 444.85, "y": 27.87}, "\u00d8240 mm (50%)": {"x": 387.18, "y": 5.25}, "\u00d8180 mm (38%)": {"x": 302.47, "y": 2.45}, "\u00d8320 mm (67%)": {"x": 489.06, "y": 10.12}, "\u00d8480 mm (100%)": {"x": 695.66, "y": 24.13}, "eff_\u00d8180 mm (38%)": {"x": 64.12, "y": 48.11}, "eff_\u00d8240 mm (50%)": {"x": 324.14, "y": 42.56}, "eff_\u00d8320 mm (67%)": {"x": 440.1, "y": 43.67}, "eff_\u00d8480 mm (100%)": {"x": 653.11, "y": 42.78}, "pow_\u00d8480 mm (100%)": {"x": 720.14, "y": 85.35}, "pow_\u00d8320 mm (67%)": {"x": 470.05, "y": 22.85}, "pow_\u00d8180 mm (38%)": {"x": 311.54, "y": 3.91}, "pow_\u00d8240 mm (50%)": {"x": 387.18, "y": 11.57}}, "label_format": "simple"} | BS10: {"spd_lbl_3": {"x": 140.85555555555555, "y": 11.76}, "eff_\u00d8900 mm": {"x": 586.44, "y": 48.71}, "pow_500 RPM": {"x": 367.02, "y": 9.72}, "eff_\u00d8500 mm": {"x": 325.8, "y": 46.21}, "eff_\u00d8600 mm": {"x": 409.76, "y": 60.71}, "spd_lbl_2": {"x": 160.62, "y": 14.87}, "500 RPM": {"x": 374.08, "y": 4.8}, "eff_spd_2": {"x": 150.85, "y": 47.85}, "eff_600 RPM": {"x": 389.3, "y": 47.06}, "eff_spd_3": {"x": 132.33, "y": 48.68}, "eff_500 RPM": {"x": 328.14, "y": 44.11}, "pow_700 RPM": {"x": 514.08, "y": 25.29}, "spd_lbl_0": {"x": 206.54, "y": 23.87}, "pow_800 RPM": {"x": 581.36, "y": 39.46}, "spd_lbl_1": {"x": 170.17, "y": 19.87}, "eff_spd_8": {"x": 436.58, "y": 54.62}, "spd_lbl_8": {"x": 345.08, "y": 6.54}, "eff_spd_6": {"x": 509.99, "y": 48.32}, "eff_spd_1": {"x": 167.62, "y": 48.4}, "spd_lbl_5": {"x": 105.23888888888891, "y": 4.6}, "spd_lbl_4": {"x": 124.4, "y": 7.84}, "pow_70_6": {"x": 545.36, "y": 25.1}, "eff_spd_0": {"x": 188.23, "y": 48.26}, "eff_spd_4": {"x": 111.36, "y": 48.82}, "pow_spd_1": {"x": 166.86, "y": 60.1}, "pow_spd_2": {"x": 156.24, "y": 43.02}, "pow_spd_3": {"x": 140.31, "y": 31.3}, "pow_spd_0": {"x": 195.68, "y": 81.25}, "pow_spd_4": {"x": 122.62, "y": 19.58}, "pow_spd_5": {"x": 99.62, "y": 7.37}, "eta_50_left": {"x": 296.95, "y": 35.53}, "eta_40_left": {"x": 210.44, "y": 37.95}, "eff_spd_5": {"x": 314.1, "y": 48.82}, "dia_lbl_1": {"x": 164.82222222222225, "y": 16.54}, "dia_lbl_2": {"x": 109.06666666666668, "y": 5.49}, "eta_45_left": {"x": 257.4, "y": 37.28}, "eta_50_6": {"x": 298.8, "y": 36.31}, "eta_52_7": {"x": 194.52222222222224, "y": 26.78}, "eta_30_left": {"x": 146.28, "y": 38.36}, "dia_lbl_3": {"x": 446.87, "y": 2.58}, "eta_20_left": {"x": 94.96, "y": 38.49}, "dia_lbl_0": {"x": 197.66666666666669, "y": 22.7}, "eff_dia_3": {"x": 102.34, "y": 52.17}, "eff_dia_2": {"x": 94.24722222222223, "y": 47.17}, "eff_dia_1": {"x": 125.40555555555557, "y": 43.83}, "eff_dia_0": {"x": 188.07222222222222, "y": 43.28}, "pow_dia_1": {"x": 133.45555555555558, "y": 23.58}, "pow_dia_0": {"x": 148.86111111111111, "y": 76.31}, "pow_dia_2": {"x": 105.10000000000001, "y": 11.38}, "pow_50_4": {"x": 413.93, "y": 25.2}, "pow_80_7": {"x": 638.03, "y": 22.85}, "pow_dia_3": {"x": 282.65, "y": 5.52}, "eta_40_right": {"x": 312.9, "y": 5.22}, "eta_52_left": {"x": 329.47, "y": 35.1}, "eta_52_right": {"x": 649.58, "y": 26.87}, "pow_20_1": {"x": 297.72, "y": 13.79}, "pow_40_3": {"x": 365.54, "y": 22.27}, "eta_45_right": {"x": 502.49, "y": 14.03}, "pow_30_2": {"x": 332.64, "y": 17.52}, "eta_50_right": {"x": 625.39, "y": 27.7}, "pow_10_0": {"x": 227.56, "y": 9.69}, "pow_600 RPM": {"x": 436.32, "y": 18.02}, "pow_900 RPM": {"x": 646.27, "y": 60.35}, "pow_1000 RPM": {"x": 711.79, "y": 89.74}, "undefined RPM": {"x": 174.89, "y": 20.17}, "1000 RPM": {"x": 710.24, "y": 23.52}, "600 RPM": {"x": 433.01, "y": 7.75}, "700 RPM": {"x": 490.54, "y": 10.85}, "800 RPM": {"x": 557.32, "y": 14.93}, "900 RPM": {"x": 625.39, "y": 19.18}, "eff_900 RPM": {"x": 588.71, "y": 44}, "eff_1000 RPM": {"x": 668.52, "y": 47}, "eff_700 RPM": {"x": 456.95, "y": 45.94}, "eff_800 RPM": {"x": 514.04, "y": 43.5}, "eff_500 RPM (50%)": {"x": 93.63, "y": 48.61}, "eff_600 RPM (60%)": {"x": 110.82, "y": 48.89}, "eff_700 RPM (70%)": {"x": 127.85, "y": 48.47}, "eff_800 RPM (80%)": {"x": 147.08, "y": 47.78}, "eff_900 RPM (90%)": {"x": 165.85, "y": 48.33}, "eff_1000 RPM (100%)": {"x": 182.36, "y": 48.75}, "pow_500 RPM (50%)": {"x": 100.59, "y": 14.11}, "pow_60_5": {"x": 444.85, "y": 27.87}, "\u00d8240 mm (50%)": {"x": 387.18, "y": 5.25}, "\u00d8180 mm (38%)": {"x": 302.47, "y": 2.45}, "\u00d8320 mm (67%)": {"x": 489.06, "y": 10.12}, "\u00d8480 mm (100%)": {"x": 695.66, "y": 24.13}, "eff_\u00d8180 mm (38%)": {"x": 64.12, "y": 48.11}, "eff_\u00d8240 mm (50%)": {"x": 324.14, "y": 42.56}, "eff_\u00d8320 mm (67%)": {"x": 440.1, "y": 43.67}, "eff_\u00d8480 mm (100%)": {"x": 653.11, "y": 42.78}, "pow_\u00d8480 mm (100%)": {"x": 720.14, "y": 85.35}, "pow_\u00d8320 mm (67%)": {"x": 470.05, "y": 22.85}, "pow_\u00d8180 mm (38%)": {"x": 311.54, "y": 3.91}, "pow_\u00d8240 mm (50%)": {"x": 387.18, "y": 11.57}} | BT10: 150SP | BU10: 1000.0;rpm | BV10: #58a6ff | BW10: fit | BX10: ls,m,m,kw | BY10: 0,37.3,0,0,;22,37.2,20,0,40.14;35.2,36.86,30,0,42.43;54,36,40,0,47.68;65,35.35,45,0,50.09;82,34.15,50,0,54.94;90.5,33.45,52,0,57.11;135.5,29.2,55,0,70.57;181,24.4,51.89,0,83.49 | BZ10: 37.302156,0.00294195,-5.55862e-05,3.1747e-08,0,0,2.213968,0.23673272,-0.0002502779,0,0,0,0.0,0.0,0.0,0,0,0,36.0275,0.043395,8.859e-05,-6.66e-08,0,0,651.60,472.57 | CA10: ls | CB10: m | CC10: m | CD10: kw | CE10: m3h | CI10: 5 | CL10: mm | CM10: mm | CN10: 0 | CO10: mm | CP10: 0 | CQ10: bar | CR10: 0 | CS10: degC | CV10: 0 | CW10: 1 | CX10: 0 | CY10: 0 | CZ10: 0 | DA10: 0 | DB10: 0 | DC10: 1 | DD10: 0 | DE10: 0 | DF10: 0 | DG10: 30 | DH10: 60 | DI10: Open | DJ10: API 610 | DK10: 3 | DM10: Metal | EM10: #ff57b9;2,solid | EN10: #3fb950;1.5,dot | EO10: #f85149;1.5,longdash | EP10: #39d3c0;1.5,dashdot | EQ10: graph | ER10: NULL | ES10: NULL | ET10: NULL | EU10: NULL | EV10: NULL | EW10: NULL | EX10: NULL | EY10: NULL | EZ10: NULL | FA10: NULL | FB10: NULL | FC10: NULL | FD10: NULL | FE10: NULL | FF10: NULL | FG10: NULL | FH10: NULL | FI10: NULL | FJ10: NULL | FK10: NULL | FL10: 3 | FM10: 3 | FN10: 2 | FO10: 2 | FP10: 3 | FQ10: 46234.784 | FR10: 46268.714
CQ12: bar
D13: =PumpOG!B2 -> SPSA | E13: =PumpOG!A2 -> 2 AF-M | F13: =[1]Sheet1!$B$2 -> SPSA | G13: =[1]Sheet1!$BU$2 -> 1800 | H13: =[1]Sheet1!$BV$2 -> 228 | L13: =[1]Sheet1!$CB$2 -> 30.15 | AQ13: =[1]Sheet1!$C$2 -> SLURRY | AU13: =[1]Sheet1!$IV$2 -> 20;30;40;45;47; | BT13: =PumpOG!$BY2 -> 2 AF-M | BY13: {=BuildCurveRawTable(E13)} -> 30.15,0,0,,;29.95,2.6,20,,;29.5,4.5,30,,;28.35,7.25,40,,;27,9.6,45,,;25,12,47,,;22.8,14.2,45,,
C14: =PumpOG!B3 -> SPSA | D14: =PumpOG!B3 -> SPSA | E14: =PumpOG!A3 -> 3 AF-M | BT14: =PumpOG!$BY3 -> 3 AF-M | BY14: {=BuildCurveRawTable(E14)} -> 29.5,0,0,,;28.9,6.3,20,,;28.5,10.35,30,,;27.9,15,40,,;26.8,22.2,50,,;25.5,28.6,55,,;23.8,35.1,57,,;22.5,40,55,,
C15: =PumpOG!B4 -> SPSA | D15: =PumpOG!B4 -> SPSA | E15: =PumpOG!A4 -> 4 AF-M | BT15: =PumpOG!$BY4 -> 4 AF-M | BY15: {=BuildCurveRawTable(E15)} -> 29.5,0,0,,;28.8,7,20,,;28.6,12.2,30,,;28.2,19.1,40,,;27.45,27.8,50,,;26.45,36,55,,;23.7,52,58,,;21.3,62,55,,
C16: =PumpOG!B5 -> SPSA | D16: =PumpOG!B5 -> SPSA | E16: =PumpOG!A5 -> 6 AF-M | BT16: =PumpOG!$BY5 -> 6 AF-M | BY16: {=BuildCurveRawTable(E16)} -> 25.18,0,0,,;25.27,20,20,,;25.1,33,30,,;24.6,47.7,40,,;24.15,58.3,45,,;23.3,72.7,50,,;21.76,93.3,55,,;20,109,56,,;18.25,124,55,,
C17: =PumpOG!B6 -> SPSA | D17: =PumpOG!B6 -> SPSA | E17: =PumpOG!A6 -> 20/18-HDM450G-RUBBER | BT17: =PumpOG!$BY6 -> 20/18-HDM450G-RUBBER;20/18-HDM450G-RUBBER;20/18-HDM450G-RUBBER | BY17: {=BuildCurveRawTable(E17)} -> 14.9,0,0,0.9,;14.9,115.3,40,0.9,;14.8,167.4,50,0.9,;14.7,252.9,60,1.1,;14.3,334.7,70,1.2,;13.9,416.5,75,1.4,;13,576.4,80,1.9,;11.9,728.9,82,2.6,;10.6,911.2,80,3.4,|28,0,0,0,;28.1,171.1,40,0,;28,245.5,50,0,;27.7,342.1,60,0,;27,461.2,70,0,;26.2,569,75,0,;24.6,773.6,80,0,;22.3,1012,82,0,;19.8,1253,80,0,|45.4,0,0,2.6,;45.4,219.4,40,2.6,;45.2,316.1,50,2.7,;44.7,431.4,60,3,;43.7,587.6,70,3.5,;42.6,721.5,75,4.1,;39.8,974.4,80,5.5,;35.9,1298,82,7.7,;32.1,1603,80,10.1,
C18: =PumpOG!B7 -> SPSA | D18: =PumpOG!B7 -> SPSA | E18: =PumpOG!A7 -> 10 AHF-M | BT18: =PumpOG!$BY7 -> 10 AHF-M | BY18: {=BuildCurveRawTable(E18)} -> 73,0,0,2.5,;73.13,130,40,2.5,;73.1,180,50,3,;72.6,251,60,4,;71.25,362,70,5,;68.5,459,75,6,;62,620,78,8,;54.2,750,75,11,
C19: =PumpOG!B8 -> SPSA | D19: =PumpOG!B8 -> SPSA | E19: =PumpOG!A8 -> 2 AHF-M | BT19: =PumpOG!$BY8 -> 2 AHF-M | BY19: {=BuildCurveRawTable(E19)} -> 57,0,0,1.6,;56.95,6.1,20,1.6,;56.5,10,30,2.15,;56.1,12.4,35,2.5,;55.6,15,40,2.85,;54.9,18,45,3.34,;54,21.5,50,4,;52.5,27,55,6.6,;50.8,33.25,57,,;48.5,39.8,55,,
C20: =PumpOG!B9 -> SPSA | D20: =PumpOG!B9 -> SPSA | E20: =PumpOG!A9 -> 3 AHF-M | BT20: =PumpOG!$BY9 -> 3 AHF-M | BY20: {=BuildCurveRawTable(E20)} -> 52.8,0,0,1.1,;53.3,10,20,1.1,;53.5,16.3,30,1.9,;53.5,24.4,40,2.55,;53.3,29,45,2.9,;53,34,50,3.4,;52.5,40.8,55,4,;51.3,50.2,60,4.9,;49,62.3,62,,;46.8,73.1,60,,;44.4,85,55,,
C21: =PumpOG!B10 -> SPSA | D21: =PumpOG!B10 -> SPSA | E21: =PumpOG!A10 -> 4 AHF-M | BT21: =PumpOG!$BY10 -> 4 AHF-M | BY21: {=BuildCurveRawTable(E21)} -> 68.8,0,0,1.8,;66.8,15.5,20,1.8,;66.05,24.4,30,2.07,;65.5,37.6,40,2.3,;64.8,50,50,2.7,;64,73.5,60,3.6,;63.2,91,64,4.7,;60.8,114.3,66,5.9,;56.9,136.2,64,,
C22: =PumpOG!B11 -> SPSA | D22: =PumpOG!B11 -> SPSA | E22: =PumpOG!A11 -> 6 AHF-M | BT22: =PumpOG!$BY11 -> 6 AHF-M | BY22: {=BuildCurveRawTable(E22)} -> 60.8,0,0,2.8,;62.05,60,30,2.8,;62.15,90,40,3,;62.15,137.5,50,3.49,;62,171,55,3.85,;61.3,215,60,4.8,;59.9,270.5,62,6,;56,317,63.5,8,;49.2,360,62,,;44.8,376,60,,
C23: =PumpOG!B12 -> SPSA | D23: =PumpOG!B12 -> SPSA | E23: =PumpOG!A12 -> 8 AHF-M | BT23: =PumpOG!$BY12 -> 8 AHF-M | BY23: {=BuildCurveRawTable(E23)} -> 62.2,0,0,2.5,;62.2,100,40,2.5,;62,140,50,3,;61.3,198,60,4,;60.6,245,65,5,;58.3,335,70,6,;55,415,71.5,8,;49.3,520,70,11,;42.7,620,65,0,
C24: =PumpOG!B13 -> SPSA | D24: =PumpOG!B13 -> SPSA | E24: =PumpOG!A13 -> AL20MG-460 | BT24: =PumpOG!$BY13 -> AL20MG-460;AL20MG-460;AL20MG-460 | BY24: {=BuildCurveRawTable(E24)} -> 14.1,0,0,1.2,;14.1,30.4,50,1.1,;13.3,43.4,60,1.1,;12.9,52.7,65,1.1,;12.5,63.8,69,1.2,;11.6,76.9,71,1.3,;11.6,93.6,71.5,1.6,;10,108.5,71,1.8,;8.7,124.6,68,2.2,|71.8,0,0,6,;70.6,68.8,50,5.9,;68.9,94.8,60,6,;67.2,114.7,65,5.7,;64.8,137.6,69,5.5,;62.3,157.4,73,5.7,;57.7,191.5,71.1,6.7,;53.1,222.5,71,8.2,;49,249.8,69,9.8,;46.5,260.3,68,10.5,|102.1,0,0,8.7,;99.2,81.8,50,8.5,;96.3,113.4,60,8.3,;93.8,135.7,65,7.9,;90.9,161.8,69,7.8,;88,182.9,71,8,;84.7,201.4,72,8.5,;81.4,221.3,72.4,9.1,;78,244.2,72,10.1,;74.3,264,71,11.2,;69.7,290.1,69,13.2,;67.7,300,68,13.9,
C25: =PumpOG!B14 -> SPSA | D25: =PumpOG!B14 -> SPSA | E25: =PumpOG!A14 -> 150 C5-M | BT25: =PumpOG!$BY14 -> 150 C5-M | BY25: {=BuildCurveRawTable(E25)} -> 118,0,0,2.5,;124,40,50,2.5,;124.5,59.8,60,2.5,;122.7,80,64,2.6,;120.5,92,66,2.8,;109.4,129.5,70,5.67,;89,169.5,66,10,;82.5,180,0,10,
... C162: =PumpOG!B151 -> SPSA | D162: =PumpOG!B151 -> SPSA | E162: =PumpOG!A151 -> 26/22-MD550TU-M | BT162: =PumpOG!$BY151 -> 26/22-MD550G-M;26/22-MD550G-M;26/22-MD550G-M | BY162: {=BuildCurveRawTable(E162)} -> 14.4,0,0,2.1,;14.5,377.2,60,2.3,;14.3,515,70,2.5,;14,664.7,78,2.5,;13.5,754.5,81,2.6,;12.9,880.2,84,2.9,;11.7,1096,86,3.2,;10.6,1281,84,3,;9.8,1401,80.9,3.3,|36.7,0,0,0,;37.1,616.8,60,0,;36.4,826.3,70,0,;35.2,1072,78,0,;34.4,1210,81,0,;33,1407,84,0,;30,1743,86,0,;27,2054,84,11.6,;25.2,2234,80.9,11.9,|51.8,0,0,8,;51.9,730.5,60,8.6,;51.2,982,70,9,;49.4,1270,78,9.5,;48.5,1443,81,10.1,;46.2,1677,84,10.5,;42.2,2066,86,11.4,;37.9,2437,84,12,;35.5,2653,80.9,12,

Sheet PumpOG
A1: INDEX_NO | B1: PumpFilter1 | C1: PumpFilter2 | D1: PumpFilter3 | E1: PumpFilter4 | F1: PumpFilter5 | G1: PumpFilter6 | H1: PumpFilter7 | I1: PumpFilter8 | J1: PumpFilter9 | K1: PumpFilter10 | L1: AltRange | M1: AltModel | N1: CURVES | O1: CURVES_E | P1: CURVES_NP | Q1: POINTS | R1: AVAILABLE | S1: BORE | T1: SHAFT | U1: ANGLE_TRIM | V1: COUPLING | W1: SLURRY | X1: MSTAGE | Y1: PER_STAGE | Z1: VARN | AA1: VARD | AB1: VAR | AC1: EFF | AD1: FULL_NP | AE1: IMP_IMP | AF1: MOTOR_IMP | AG1: NP_DOWN | AH1: UNIT_FLOW | AI1: CON_FLOW | AJ1: UNIT_HEAD | AK1: CON_HEAD | AL1: Q_MIN | AM1: Q_MAX | AN1: USER_EOC_MIN | AO1: USER_EOC_MAX | AP1: KW_MIN | AQ1: KW_MAX | AR1: HD_MAX | AS1: HD_MIN | AT1: MAX_EFF | AU1: MinAllow | AV1: MaxAllow | AW1: BEP_FLOW | AX1: BEP_HEAD | AY1: BEP_KW | AZ1: BEP_NP | BA1: SO_HEAD | BB1: SO_KW | BC1: NS | BD1: NSS | BE1: B_DIAM | BF1: EFF1 | BG1: EFF2 | BH1: EFF3 | BI1: MIN_IMP | BJ1: MAX_IMP | BK1: IMP_TRACKWIDTH | BL1: IMP_EYEDIAM | BM1: MIN_SPEED | BN1: MAX_SPEED | BO1: MIN_STAGES | BP1: MAX_STAGES | BQ1: MIN_TEMP | BR1: MAX_TEMP | BS1: MIN_VISC | BT1: MAX_VISC | BU1: N_TEST | BV1: D_TEST | BW1: N_GRAPH | BX1: MTF_FLOW | BY1: M_NAME | BZ1: M_KWM | CA1: M_IMP | CB1: M_HEAD0 | CC1: M_FLOW0 | CD1: M_FLOWMIN | CE1: M_HEAD | CF1: M_KW | CG1: M_FLOW | CI1: M_NP | CK1: M_COQ | CL1: M_COH | CM1: M_COE | CN1: M_CON | CO1: M_SO_KW | CP1: NEW_VER | CQ1: MAX_STG2 | CR1: MAX_SOLID | CS1: D_PIPE | CT1: CURVE_NO | CU1: FRAME | CV1: EXPEL1 | CW1: EXPEL2 | CX1: MAXP_W | CY1: MAXP_S | CZ1: PRESS_FACT | DA1: MAXP_BEARING | DB1: PDF_NAME | DC1: PD | DD1: VISC | DE1: ExternalNotes | DF1: InternalNotes | DG1: DesignerNotes | DH1: WarningNotes | DI1: PumpExtra0 | DJ1: PumpExtra1 | DK1: PumpExtra2 | DL1: PumpExtra3 | DM1: PumpExtra4 | DN1: PumpExtra5 | DO1: PumpExtra6 | DP1: PumpExtra7 | DQ1: PumpExtra8 | DR1: PumpExtra9 | DS1: PumpExtra10 | DT1: PumpExtra11 | DU1: PumpExtra12 | DV1: PumpExtra13 | DW1: PumpExtra14 | DX1: PumpExtra15 | DY1: PumpExtra16 | DZ1: PumpExtra17 | EA1: PumpExtra18 | EB1: PumpExtra19 | EC1: PumpExtra20 | ED1: PumpExtra21 | EE1: PumpExtra22 | EF1: PumpExtra23 | EG1: PumpExtra24 | EH1: PumpExtra25 | EI1: PumpExtra26 | EJ1: PumpExtra27 | EK1: PumpExtra28 | EL1: PumpExtra29 | EM1: PumpExtra30 | EN1: PumpExtra31 | EO1: PumpExtra32 | EP1: PumpExtra33 | EQ1: PumpExtra34 | ER1: PumpExtra35 | ES1: PumpExtra36 | ET1: PumpExtra37 | EU1: PumpExtra38 | EV1: PumpExtra39 | EW1: M_COISO | EX1: M_INCISO | EY1: M_TOPISO | EZ1: M_BOTISO | FA1: Polynomial | FB1: M_EFF | FC1: M_DIAM | FD1: M_MULTI | FE1: M_PLOT | FF1: X_MIN | FG1: X_MAX | FH1: X_INT | FI1: X_1 | FJ1: X_2 | FK1: H_MIN | FL1: H_MAX | FM1: H_INT | FN1: H_1 | FO1: H_2 | FP1: E_MIN | FQ1: E_MAX | FR1: E_INT | FS1: E_1 | FT1: E_2 | FU1: KW_MIN1 | FV1: KW_MAX1 | FW1: KW_1 | FX1: KW_2 | FY1: KW_INT | FZ1: NP_MIN | GA1: NP_MAX | GB1: NP_INT | GC1: NP_1 | GD1: NP_2 | GE1: N_MIN | GF1: N_MAX | GG1: N_INT | GH1: CURVE_CREATED_DATE | GI1: CURVE_REV_DETAILS | GJ1: CREATED_BY | GK1: UPDATED_BY | GL1: BUILD_DESIGNATION | GM1: CASING_MOUNTING | GN1: SUCT_DIAM | GO1: DIS_DIAM | GP1: MAX_CW | GQ1: CURVE_REV | GR1: CURVE_DATE | GS1: Image | GT1: GA | GU1: DesignNotes | GV1: CON_KW | GW1: M_KW0 | GX1: M_KW1 | GY1: M_NP1 | GZ1: ORDER1 | HA1: ORDER2 | HB1: ORDER3 | HC1: ORDER4 | HD1: M_LABEL | HE1: M_LINE | HF1: M_KWISO | HG1: M_NPISO | HH1: MIN_ORFD | HI1: MAX_ORFD | HJ1: QMIN_HEAD | HK1: 120BEP_HEAD | HL1: 120BEP_KW | HM1: CURVE_APPROVED_BY | HN1: CURVE_APPROVED_DATE | HO1: PumpExtra40 | HP1: PumpExtra41 | HQ1: PumpExtra42 | HR1: PumpExtra43 | HS1: PumpExtra44 | HT1: PumpExtra45 | HU1: PumpExtra46 | HV1: PumpExtra47 | HW1: PumpExtra48 | HX1: PumpExtra49 | HY1: PumpExtra50 | HZ1: PumpExtra51 | IA1: PumpExtra52 | IB1: PumpExtra53 | IC1: PumpExtra54 | ID1: PumpExtra55 | IE1: PumpExtra56 | IF1: PumpExtra57 | IG1: PumpExtra58 | IH1: PumpExtra59 | II1: PumpExtra60 | IJ1: PumpExtra61 | IK1: PumpExtra62 | IL1: PumpExtra63 | IM1: PumpExtra64 | IN1: PumpExtra65 | IO1: PumpExtra66 | IP1: PumpExtra67 | IQ1: PumpExtra68 | IR1: PumpExtra69 | IS1: MAX_EFF_DB | IT1: BEP_FLOW_DB | IU1: BEP_HEAD_DB | IV1: BEP_KW_DB | IW1: BEP_NP_DB | IX1: M_EFFISO | IY1: ISO_ERROR | IZ1: ISO_MULTIPLIER | JA1: ISO_TOP | JB1: ISO_BOT | JC1: UNIT_PRESSURE | JD1: M_SPEED | JE1: M_CAL | JF1: M_GRAPH_MODE | JG1: M_GRAPH_IMG_PATH | JH1: OrfBEP | JI1: DBL_SUCTION | JJ1: SELF_PRIMING | JK1: BEOC_KW | JL1: BEOC_NP | JM1: BEP_CURVENO
A2: 2 AF-M | B2: SPSA | C2: SLURRY | D2: OPEN | E2: AF | F2: METAL | G2: 5 | H2: WPG2AF31 | I2: WARMAN | J2: N/A | L2: AF | M2: 2 AF-M | N2: 1 | O2: 1 | P2: 1 | Q2: 7 | R2: 2 | S2: 0 | T2: 0 | U2: 0 | V2: NULL | W2: 1 | X2: 0 | Y2: 0 | Z2: 1 | AA2: 0 | AB2: 1 | AC2: NULL | AD2: 0 | AE2: 0 | AF2: 0 | AG2: 0 | AH2: l/sec | AI2: 1 | AJ2: m | AK2: 1 | AL2: 2.6 | AM2: 14.2 | AN2: 0 | AO2: 0 | AP2: 0 | AQ2: 0 | AR2: 30.15 | AS2: 22.8 | AT2: 46.91 | AU2: 0 | AV2: 0 | AW2: 12.02 | AX2: 25.01 | AY2: 6.28 | AZ2: 0 | BA2: 30.15 | BB2: 0 | BC2: 18 | BD2: 0 | BE2: 0 | BF2: 0 | BG2: 0 | BH2: 0 | BI2: 0 | BJ2: 0 | BK2: 0 | BL2: 0 | BM2: 800 | BN2: 1800 | BO2: 0 | BP2: 0 | BQ2: 0 | BR2: 0 | BS2: 0 | BT2: 0 | BU2: 1800 | BV2: 228 | BW2: NULL | BX2: 0 | BY2: 2 AF-M | CA2: 1800 | CB2: 30.15 | CC2: 14.2 | CD2: NULL | CE2: 30.15;29.95;29.5;28.35;27;25;22.8 | CF2: 0;20;30;40;45;47;45 | CG2: 0;2.6;4.5;7.25;9.6;12;14.2 | CH2: =_xlfn.TEXTJOIN(";",TRUE,MID(C1,1,SEARCH(";",C1&";")-1)&","&MID(C2,1,SEARCH(";",C2&";")-1)&","&MID(C3,1,SEARCH(";",C3&";")-1)) -> PumpFilter2,SLURRY,SLURRY | CK2: 1 | CL2: 30.152 .00754 -.0331063 -.000176159 -7.015E-06 | CM2: 0.002 9.44679 -0.7765408 0.041264318-0.001247287 | CN2: 0 0 0 0 0 | CP2: NULL | CQ2: NULL | CR2: 35 | CS2: 0 | CT2: VF50 (5) | CX2: 0 | CY2: 0 | CZ2: 0 | DA2: 0 | DB2: curves\af\2 af-m | DC2: 0 | DD2: 0 | DI2: 2 AF | DJ2: BAF2127 | DK2: 50 | DQ2: QV | DR2: 30 | DS2: 0 | DT2: 0 | DU2: 0 | DV2: 0 | EW2: NULL | EX2: NULL | EY2: NULL | EZ2: NULL | FA2: 4 | FB2: NULL | FF2: 0 | FG2: 0 | FH2: 0 | FI2: 0 | FJ2: 0 | FK2: 0 | FL2: 0 | FM2: 0 | FN2: 0 | FO2: 0 | FP2: 0 | FQ2: 0 | FR2: 0 | FS2: 0 | FT2: 0 | FU2: 0 | FV2: 0 | FW2: 0 | FX2: 0 | FY2: 0 | FZ2: 0 | GA2: 0 | GB2: 0 | GC2: 0 | GD2: 0 | GE2: NULL | GF2: NULL | GG2: NULL | GH2: 44648 | GI2: Curve loaded from Warman / Weir printed curve | GJ2: Gugu Khoza | GK2: Pieter du Plessis | GN2: 76 | GO2: 51 | GP2: 0 | GQ2: A | GR2: 44648 | GV2: NULL | GW2: NULL | GX2: NULL | GY2: NULL | GZ2: NULL | HA2: NULL | HB2: NULL | HC2: NULL | HD2: NULL | HE2: NULL | HH2: 0 | HI2: 0 | HJ2: 29.94 | HK2: 22.54 | HL2: 7.16 | HN2: NULL | IS2: 0 | IT2: 0 | IU2: 0 | IV2: 0 | IW2: 0 | IX2: 20;30;40;45;47; | IY2: 0 | IZ2: 0 | JA2: 0 | JB2: 0 | JC2: bar a | JD2: 800;1000;1200;1400;1600;1800 | JF2: 0 | JH2: NULL | JI2: 0 | JJ2: NULL | JK2: 7.05 | JL2: 0 | JM2: 1
A3: 3 AF-M | B3: SPSA | C3: SLURRY | D3: OPEN | E3: AF | F3: METAL | G3: 5 | H3: WPG3AF31 | I3: WARMAN | J3: N/A | L3: AF | M3: 3 AF-M | N3: 1 | O3: 1 | P3: 1 | Q3: 8 | R3: 2 | S3: 0 | T3: 0 | U3: 0 | V3: NULL | W3: 1 | X3: 0 | Y3: 0 | Z3: 1 | AA3: 0 | AB3: 1 | AC3: NULL | AD3: 0 | AE3: 0 | AF3: 0 | AG3: 0 | AH3: l/sec | AI3: 1 | AJ3: m | AK3: 1 | AL3: 6.3 | AM3: 40 | AN3: 0 | AO3: 0 | AP3: 0 | AQ3: 0 | AR3: 29.5 | AS3: 22.5 | AT3: 56.68 | AU3: 0 | AV3: 0 | AW3: 34.25 | AX3: 24.06 | AY3: 14.25 | AZ3: 0 | BA3: 29.5 | BB3: 0 | BC3: 26 | BD3: 0 | BE3: 0 | BF3: 0 | BG3: 0 | BH3: 0 | BI3: 0 | BJ3: 0 | BK3: 0 | BL3: 0 | BM3: 700 | BN3: 1500 | BO3: 0 | BP3: 0 | BQ3: 0 | BR3: 0 | BS3: 0 | BT3: 0 | BU3: 1500 | BV3: 267 | BW3: NULL | BX3: 0 | BY3: 3 AF-M | CA3: 1500 | CB3: 29.5 | CC3: 40 | CD3: NULL | CE3: 29.5;28.9;28.5;27.9;26.8;25.5;23.8;22.5 | CF3: 0;20;30;40;50;55;57;55 | CG3: 0;6.3;10.35;15;22.2;28.6;35.1;40 | CK3: 5 | CL3: 29.504 -.5241 .056773 -.022697513 .001260996 | CM3: -0.03 18.16803 -1.9086488 0.102655657-0.005036493 | CN3: 0 0 0 0 0 | CP3: NULL | CQ3: NULL | CR3: 38 | CS3: 0 | CT3: VF80 (5) | CX3: 0 | CY3: 0 | CZ3: 0 | DA3: 0 | DB3: curves\af\3 af-m | DC3: 0 | DD3: 0 | DI3: 3 AF | DJ3: CAF3127 | DK3: 80 | DQ3: QV | DR3: 30 | DS3: 0 | DT3: 0 | DU3: 0 | DV3: 0 | EW3: NULL | EX3: NULL | EY3: NULL | EZ3: NULL | FA3: 4 | FB3: NULL | FF3: 0 | FG3: 0 | FH3: 0 | FI3: 0 | FJ3: 0 | FK3: 0 | FL3: 0 | FM3: 0 | FN3: 0 | FO3: 0 | FP3: 0 | FQ3: 0 | FR3: 0 | FS3: 0 | FT3: 0 | FU3: 0 | FV3: 0 | FW3: 0 | FX3: 0 | FY3: 0 | FZ3: 0 | GA3: 0 | GB3: 0 | GC3: 0 | GD3: 0 | GE3: NULL | GF3: NULL | GG3: NULL | GH3: 44648 | GI3: Curve loaded from Warman / Weir printed curve | GJ3: Gugu Khoza | GK3: Pieter du Plessis | GN3: 76.2 | GO3: 76 | GP3: 0 | GQ3: A | GR3: 44648 | GV3: NULL | GW3: NULL | GX3: NULL | GY3: NULL | GZ3: NULL | HA3: NULL | HB3: NULL | HC3: NULL | HD3: NULL | HE3: NULL | HH3: 0 | HI3: 0 | HJ3: 28.89 | HK3: 22.18 | HL3: 16.44 | HN3: NULL | IS3: 0 | IT3: 0 | IU3: 0 | IV3: 0 | IW3: 0 | IX3: 20;30;40;50;55;57; | IY3: 0 | IZ3: 0 | JA3: 0 | JB3: 0 | JC3: bar a | JD3: 700;900;1100;1300;1500;1500 | JF3: 0 | JH3: NULL | JI3: 0 | JJ3: NULL | JK3: 16.04 | JL3: 0 | JM3: 1
A4: 4 AF-M | B4: SPSA | C4: SLURRY | D4: OPEN | E4: AF | F4: METAL | G4: 5 | H4: WPG4AF31 | I4: WARMAN | J4: N/A | L4: AF | M4: 4 AF-M | N4: 1 | O4: 1 | P4: 1 | Q4: 8 | R4: 2 | S4: 0 | T4: 0 | U4: 0 | V4: NULL | W4: 1 | X4: 0 | Y4: 0 | Z4: 1 | AA4: 0 | AB4: 1 | AC4: NULL | AD4: 0 | AE4: 0 | AF4: 0 | AG4: 0 | AH4: l/sec | AI4: 1 | AJ4: m | AK4: 1 | AL4: 7 | AM4: 62 | AN4: 0 | AO4: 0 | AP4: 0 | AQ4: 0 | AR4: 29.5 | AS4: 21.3 | AT4: 58.15 | AU4: 0 | AV4: 0 | AW4: 49.83 | AX4: 24.13 | AY4: 20.27 | AZ4: 0 | BA4: 29.5 | BB4: 0 | BC4: 23 | BD4: 0 | BE4: 0 | BF4: 0 | BG4: 0 | BH4: 0 | BI4: 0 | BJ4: 0 | BK4: 0 | BL4: 0 | BM4: 500 | BN4: 1100 | BO4: 0 | BP4: 0 | BQ4: 0 | BR4: 0 | BS4: 0 | BT4: 0 | BU4: 1100 | BV4: 381 | BW4: NULL | BX4: 0 | BY4: 4 AF-M | CA4: 1100 | CB4: 29.5 | CC4: 62 | CD4: NULL | CE4: 29.5;28.8;28.6;28.2;27.45;26.45;23.7;21.3 | CF4: 0;20;30;40;50;55;58;55 | CG4: 0;7;12.2;19.1;27.8;36;52;62 | CK4: 5 | CL4: 29.468 -.50128 .0821462 -.012479172 .000390048 | CM4: 0.206 16.02869 -1.7999602 0.111659393-0.003390102 | CN4: 0 0 0 0 0 | CP4: NULL | CQ4: NULL | CR4: 55 | CS4: 0 | CT4: VF100 (5) | CX4: 0 | CY4: 0 | CZ4: 0 | DA4: 0 | DB4: curves\af\4 af-m | DC4: 0 | DD4: 0 | DI4: 4 AF | DJ4: RAF4127 | DK4: 100 | DQ4: RV | DR4: 75 | DS4: 0 | DT4: 0 | DU4: 0 | DV4: 0 | EW4: NULL | EX4: NULL | EY4: NULL | EZ4: NULL | FA4: 4 | FB4: NULL | FF4: 0 | FG4: 0 | FH4: 0 | FI4: 0 | FJ4: 0 | FK4: 0 | FL4: 0 | FM4: 0 | FN4: 0 | FO4: 0 | FP4: 0 | FQ4: 0 | FR4: 0 | FS4: 0 | FT4: 0 | FU4: 0 | FV4: 0 | FW4: 0 | FX4: 0 | FY4: 0 | FZ4: 0 | GA4: 0 | GB4: 0 | GC4: 0 | GD4: 0 | GE4: NULL | GF4: NULL | GG4: NULL | GH4: 44648 | GI4: Curve loaded from Warman / Weir printed curve | GJ4: Gugu Khoza | GK4: Pieter du Plessis | GN4: 152 | GO4: 102 | GP4: 0 | GQ4: A | GR4: 44648 | GV4: NULL | GW4: NULL | GX4: NULL | GY4: NULL | GZ4: NULL | HA4: NULL | HB4: NULL | HC4: NULL | HD4: NULL | HE4: NULL | HH4: 0 | HI4: 0 | HJ4: 28.89 | HK4: 21.86 | HL4: 22.84 | HN4: NULL | IS4: 0 | IT4: 0 | IU4: 0 | IV4: 0 | IW4: 0 | IX4: 20;30;40;50;55;58; | IY4: 0 | IZ4: 0 | JA4: 0 | JB4: 0 | JC4: bar a | JD4: 500;600;700;800;900;1000;1100 | JF4: 0 | JH4: NULL | JI4: 0 | JJ4: NULL | JK4: 23.54 | JL4: 0 | JM4: 1
